Workbook
Name 出入境事由: [1]Sheet2!$B$2:$B$14
Name 国籍: [1]Sheet2!$C$2:$C$284
Name 九十天期_90days: 'Tnng App'!$C$35
Name 签证种类: [1]Sheet2!$E$2:$E$21
Name 性别: [1]Sheet2!$F$2:$F$5
Name 证件类别: [1]Sheet2!$G$2:$G$4
Name 职务: [1]Sheet2!$A$2:$A$26

Sheet Cstm Rgd
E3: 南沙保税港区
E5: 进出境运输工具登记表
E8: 船舶编号：UN | F8: ='Gen Inb'!I10 -> IMO:1032452
D18: 船名（中文）： | E18: ='Gen Inb'!I6 -> 马士基奋进
D19: 船名（英文）： | E19: ='Gen Inb'!I7 -> ERASMUS EFFORT
D20: 国籍 ： | E20: ='Gen Inb'!F8 -> 巴拿马
D21: 所属企业 ： | E21: ='IMO Gen Inb'!I21 -> 船公司：马士基（中国）航运有限公司青岛分公司
D22: 进港日期 ： | E22: ='Gen Inb'!X6 -> 46238
D23: 出港日期 ： | E23: ='Gen Outb'!X6 -> 44160

Sheet Cstm Inb
D3: 船舶进境情况
B5: 航线 | C5: 上航次 | E5: 南沙新港 | G5: —— | H5: ='Gen Inb'!W8 -> 胡志明市
C6: 本航次 | E6: ='Gen Inb'!W8 -> 胡志明市 | G6: —— | H6: ='Gen Inb'!S6 -> 南沙新港
B7: 船员人数 | C7: 中国籍 | D7: =COUNTIF('Crew Inb'!G11:G30,"Chinese") -> 0 | G7: 外国籍 | H7: =COUNTA('Crew Inb'!C11:C30)-COUNTIF('Crew Inb'!G11:G30,"Chinese") -> 20
B8: 载货情况 | C8: 进口货物 | D8: 20 | E8: 40 | G8: 转关货物 | H8: 20 | I8: 40
D9: 67 | E9: 68 | H9: 0 | I9: 0
C10: 转运货物 | D10: 20 | E10: 40 | G10: 空柜 | H10: 20 | I10: 40
D11: 0 | E11: 0 | H11: 0 | I11: 0
B12: 船舶吨位 | C12: 总吨位 | D12: ='Parts A'!E5 -> 9562 | G12: 净吨位 | H12: ='Parts A'!G5 -> 4523
B13: 吨税执照
B14: 海关关封 | C14: 字第 | G14: 号
B15: 联检时间 | C15: ='Gen Inb'!X6 -> 46238 | D15: 联检地点 | E15: ='Gen Inb'!S6 -> 南沙新港 | G15: 经办人员
B16: 烟酒情况 | C16: 烟数量 | E16: 酒数量 | H16: 是否加封
B17: 单证附录：
B18: （一）总申报单； | F18: （六）吨税复印件；
B19: （二）货物申报单； | F19: （七）船舶舱单；
B20: （三）船员名单； | F20: （八）其他（请列明）；
B21: （四）船员物品清单； | F21: ____________________________
B22: （五）船舶物品清单； | F22: ____________________________

Sheet Cstm Outb
D3: 船舶出境情况
B5: 航线 | E5: ='Gen Outb'!S6 -> 南沙新港 | G5: —— | H5: ='Gen Outb'!W8 -> 胡志明市
B6: 船员人数 | C6: 中国籍 | D6: =COUNTIF('Crew Outb'!G11:G45,"Chinese") -> 0 | G6: 外国籍 | H6: =COUNTA('Crew Outb'!C11:C45)-COUNTIF('Crew Outb'!G11:G45,"CHINESE") -> 21
B7: 载货情况 | C7: 出口货物 | D7: 20 | E7: 40 | G7: 转关货物 | H7: 20 | I7: 40
H8: 0 | I8: 0
C9: 转运货物 | D9: 20 | E9: 40 | G9: 空柜 | H9: 20 | I9: 40
D10: 133 | E10: 324 | H10: 0 | I10: 0
B11: 海关关封 | C11: （南沙保税港区）2012字第 | G11: 号
B12: 联检时间 | C12: ='Gen Outb'!X6 -> 44160 | D12: 联检地点 | E12: ='Gen Outb'!S6 -> 南沙新港 | G12: 经办人员
B14: 烟酒情况 | C14: 烟数量 | E14: 酒数量 | H14: 是否加封
B16: 单证附录：
B17: （一）总申报单； | F17: （六）吨税复印件；
B18: （二）货物申报单； | F18: （七）船舶舱单；
B19: （三）船员名单； | F19: （八）其他（请列明）；
B20: （四）船员物品清单； | F20: ____________________________
B21: （五）船舶物品清单； | F21: ____________________________

Sheet Cstm Prob
E3: 待处理问题登记：

Sheet Gen Inb
A1: IMO Convention on Facilitation of International Maritime Traffic | B1: 总 申 报 单
B2: GENERAL DECLARATION
B3: 编号: | O3: V | P3: 抵港 | V3: 离港
B4: No. | P4: Arrival | V4: Departure
B6: 1.船舶名称及种类 | I6: ='Parts A'!B3 -> 马士基奋进 | M6: ='Parts A'!J3 -> 集装箱轮 | O6: 2.抵/离港口 | S6: 南沙新港 | V6: 3.抵/离日期及时间 | X6: 46238
B7: Name and description of ship | I7: ='Parts A'!B4 -> ERASMUS EFFORT | M7: ='Parts A'!J4 -> Container | O7: Port of arrival/departure | S7: NANSHA NEW PORT | V7: Date-time of arrival/departure
B8: 4.船舶国籍 | F8: ='Parts A'!E3 -> 巴拿马 | I8: 5.船长姓名 | M8: ='Crew Inb'!C11 -> 李继祥 | O8: 6.驶来港/目的地 | W8: 胡志明市 | Z8: 丹戎帕拉帕斯 | AB8: 马来西亚
B9: Nationality of ship | F9: ='Parts A'!E4 -> PANAMA | I9: Name of master | O9: Port arrived from/port of destination | W9: HO CHI MINH CITY | Z9: TANJUNG PELEPAS | AB9: MALAYSIA
B10: 7.登记证书Certificate of registry | I10: ='Parts A'!B5 -> IMO:1032452 | O10: 8.船舶代理名称及地址 | Z10: 新加坡
B11: 56766-25 | O11: Name and address of ship's agent | Z11: SINGAPORE
B12: 9.总吨位 | E12: ='Parts A'!E5 -> 9562 | I12: 10.净吨位 | L12: ='Parts A'!G5 -> 4523 | O12: 广州港中联国际船务代理有限公司 | W12: 冼家昇 | Z12: 香港
B13: Gross tonnage | I13: Net tonnage | W13: 440182200003200357 | Z13: HONGKONG
B14: 11.在港泊位 | K14: 二期W | O14: 91440101MA5AQA0F7M | W14: 18664696130 | Z14: 巴生港
B15: Position of the ship in the port(berth of station) | Z15: PORT KLANG
B16: 12.航次摘要(先后挂靠港口、并在即将卸下留存货物的港名下划线标注）
B17: Berth particulars of voyage(previous and subsequent ports of call:underline where remaining cargo will be discharged)
G18: =W8 -> 胡志明市 | K18: —— | M18: =S6 -> 南沙新港 | R18: —— | T18: ='Gen Outb'!W8 -> 胡志明市
B19: =W9 -> HO CHI MINH CITY | G19: =W9 -> HO CHI MINH CITY | M19: =S7 -> NANSHA NEW PORT | T19: ='Gen Outb'!W9 -> HO CHI MINH CITY
B20: 13.货物摘要说明
B21: Brief description of the cargo | J21: 总重量： | L21: =W22+W23 -> 12059 | M21: =IF(AND(W22=0,W23=0),"NIL",W22+W23) -> 12059 | O21: 吨
E22: 进口柜： | F22: =IF('Cstm Inb'!D9+'Cstm Inb'!E9+'Cstm Inb'!H9+'Cstm Inb'!I9+'Cstm Inb'!D11+'Cstm Inb'!E11+'Cstm Inb'!H11+'Cstm Inb'!I11=0,"NIL","20F×"&'Cstm Inb'!D9+'Cstm Inb'!H9+'Cstm Inb'!D11&", 40F×"&'Cstm Inb'!E9+'Cstm Inb'!I9+'Cstm Inb'!E11&", 20E×"&'Cstm Inb'!H11&", 40E×"&'Cstm Inb'!I11) -> 20F×67, 40F×68, 20E×0, 40E×0 | P22: 总共： | R22: ='Cstm Inb'!D9+'Cstm Inb'!H9+'Cstm Inb'!D11+'Cstm Inb'!H11+('Cstm Inb'!E9+'Cstm Inb'!I9+'Cstm Inb'!E11+'Cstm Inb'!I11)*2 -> 203 | T22: TEU | V22: ， | W22: 2919 | X22: 吨；
E23: 过境柜： | F23: =IF('Cstm Outb'!D10+'Cstm Outb'!E10+'Cstm Outb'!H10+'Cstm Outb'!I10=0,"NIL","20F×"&'Cstm Outb'!D10&", 40F×"&'Cstm Outb'!E10) -> 20F×133, 40F×324 | P23: 总共： | R23: ='Cstm Outb'!D10+'Cstm Outb'!H10+('Cstm Outb'!E10+'Cstm Outb'!I10)*2 -> 781 | T23: TEU | V23: ， | W23: =('Cstm Outb'!D10+'Cstm Outb'!E10)*20+'Cstm Outb'!H10+'Cstm Outb'!I10*2 -> 9140 | X23: 吨；
B24: 14.船员人数(含船长) | H24: 19 | I24: 15.旅客人数 | N24: nil | O24: 16.备 注 | R24: 无武器 | W24: 船员国籍分布：
B25: Number of crew(incl. Master) | I25: Number of Passengers | O25: Remarks | R25: No Weapen | W25: 中国5名 | X25: 越南1名
B26: 附件(标明份数) | O26: 船舶呼号： | R26: ='Parts A'!B6 -> 3E8968 | W26: 孟加拉国1名
B27: Attached documents(indicate number of copies) | O27: MMSI： | R27: 352005770 | W27: 菲律宾1名
B28: 17.货物申报单 | I28: 18.船用物品申报单 | O28: 船公司： | R28: 马士基（中国）航运有限公司青岛分公司 | W28: 印度尼西亚1名
B29: Cargo Declaration | I29: Ship's Stord Declaration | O29: 航次：进/出 | R29: 631NI | W29: 缅甸10名
B30: 19.船员名单. | H30: 1 | I30: 20.旅客名单 | N30: nil | O30: 21.船长或其代理人签名、日期
B31: Crew List | I31: Passenger List | O31: Date and signature by master,authorized agent or officer
B32: 22.船员物品申报单* | H32: 1 | I32: 23.航海健康申报书
B33: Crew's Effects Declaration | I33: Maritime Declaration of Health
B34: 检查机关签注
B35: For official use

Sheet Cgo Inb
A1: IMO Convention on Facilitation of International Maritime Traffic | B1: 货 物 申 报 单
B2: CARGO DECLARATION
B3: 编号 | E3: 抵港 | F3: 离港 | G3: 第 页
B4: No. | E4: Arrival | F4: Departure | G4: Page No.
B6: 1. 船 名 | C6: ='Gen Inb'!I6 -> 马士基奋进 | F6: 2. 申报港 | G6: ='Gen Inb'!S6 -> 南沙新港
B7: Name of ship | C7: ='Gen Inb'!I7 -> ERASMUS EFFORT | F7: Port where report is made | G7: ='Gen Inb'!S7 -> NANSHA NEW PORT
B8: 3. 船舶国籍 | C8: ='Gen Inb'!F8 -> 巴拿马 | D8: 4. 船长姓名 | E8: ='Gen Inb'!M8 -> 李继祥 | F8: 5. 装卸港 | G8: ='Gen Inb'!S6 -> 南沙新港
B9: Nationality of ship | C9: ='Gen Inb'!F9 -> PANAMA | D9: Name of master | F9: Port of loading/Port of discharge | G9: ='Gen Inb'!S7 -> NANSHA NEW PORT
B10: 6. 标记及号码 | C10: 7. 包件的种类和数量 | F10: 8. 毛 重 | G10: 9. 单 位
B11: Marks and Nos. | C11: Number and kind of packages, description of goods | F11: Gross weight | G11: measurement
D15: ='Gen Inb'!J21&'Gen Inb'!M21&" "&'Gen Inb'!O21 -> 总重量：12059 吨
C17: ='Gen Inb'!E22&'Gen Inb'!F22 -> 进口柜：20F×67, 40F×68, 20E×0, 40E×0
D18: ='Gen Inb'!P22&'Gen Inb'!R22&" "&'Gen Inb'!T22&'Gen Inb'!V22&'Gen Inb'!W22&" "&'Gen Inb'!X22 -> 总共：203 TEU，2919 吨；
C19: ='Gen Inb'!E23&'Gen Inb'!F23 -> 过境柜：20F×133, 40F×324
D20: ='Gen Inb'!P23&'Gen Inb'!R23&" "&'Gen Inb'!T23&'Gen Inb'!V23&'Gen Inb'!W23&" "&'Gen Inb'!X23 -> 总共：781 TEU，9140 吨；
C26: ='Gen Inb'!O12&"："&'Gen Inb'!W12 -> 广州港中联国际船务代理有限公司：冼家昇
D27: ='Gen Inb'!W14 -> 18664696130
B34: 10. 船长或其代理人签名、日期
B35: Date and signature by master, authorized agent or officer
F37: 中华人民共和国海事局监制
F38: 98版本 仿造必究

Sheet Gen Outb
A1: IMO Convention on Facilitation of International Maritime Traffic | B1: 总 申 报 单
B2: GENERAL DECLARATION
B3: 编号: | P3: 抵港 | U3: V | V3: 离港
B4: No. | P4: Arrival | V4: Departure
B6: 1.船舶名称及种类 | I6: ='Gen Inb'!I6 -> 马士基奋进 | M6: ='Gen Inb'!M6:N6 -> 集装箱轮 | O6: 2.抵/离港口 | S6: ='Gen Inb'!S6 -> 南沙新港 | V6: 3.抵/离日期及时间 | X6: 44160
B7: Name and description of ship | I7: ='Gen Inb'!I7 -> ERASMUS EFFORT | M7: ='Gen Inb'!M7:N7 -> Container | O7: Port of arrival/departure | S7: ='Gen Inb'!S7 -> NANSHA NEW PORT | V7: Date-time of arrival/departure
B8: 4.船舶国籍 | F8: ='Gen Inb'!F8 -> 巴拿马 | I8: 5.船长姓名 | M8: ='Crew Outb'!C11&" "&'Crew Outb'!D11 -> BINKOVSKY ANDRIY | O8: 6.驶来港/目的地 | W8: 胡志明市 | AA8: 丹戎帕拉帕斯 | AC8: 马来西亚
B9: Nationality of ship | F9: ='Gen Inb'!F9 -> PANAMA | I9: Name of master | O9: Port arrived from/port of destination | W9: HO CHI MINH CITY | AA9: TANJUNG PELEPAS | AC9: MALAYSIA
B10: 7.登记证书（港口、日期、号码） | I10: ='Gen Inb'!I10 -> IMO:1032452 | O10: 8.船舶代理名称及地址 | AA10: 新加坡
B11: Certificate of registry(port;date;number) | O11: Name and address of ship's agent | AA11: SINGAPORE
B12: 9.总吨位 | E12: ='Gen Inb'!E12 -> 9562 | I12: 10.净吨位 | L12: ='Gen Inb'!L12 -> 4523 | P12: ='Gen Inb'!P12 -> 0 | V12: 曾康达 | AA12: 香港
B13: Gross tonnage | I13: Net tonnage | AA13: HONGKONG
B14: 11.在港泊位 | K14: ='Gen Inb'!K14:N15 -> 二期W | P14: ='Gen Inb'!O14 -> 91440101MA5AQA0F7M | V14: 18825058579 | AA14: 巴生港
B15: Position of the ship in the port(berth of station) | AA15: PORT KLANG
B16: 12.航次摘要(先后挂靠港口、并在即将卸下留存货物的港名下划线标注）
B17: Berth particulars of voyage(previous and subsequent ports of call:underline where remaining cargo will be discharged)
G18: ='Gen Inb'!W8 -> 胡志明市 | K18: —— | M18: =S6 -> 南沙新港 | R18: —— | T18: =W8 -> 胡志明市
B19: ='Gen Inb'!W9 -> HO CHI MINH CITY | G19: ='Gen Inb'!W9 -> HO CHI MINH CITY | M19: =S7 -> NANSHA NEW PORT | T19: =W9 -> HO CHI MINH CITY
B20: 13.货物摘要说明
B21: Brief description of the cargo | J21: 总重量： | L21: =W22+W23 -> 17396.5 | M21: =IF(AND(W22=0,W23=0),"NIL",W22+W23) -> 17396.5 | O21: 吨
E22: 出口柜： | F22: =IF('Cstm Outb'!D8+'Cstm Outb'!E8=0,"NIL","20F×"&'Cstm Outb'!D8&", 40F×"&'Cstm Outb'!E8&", 20E×"&'Cstm Outb'!H10&", 40E×"&'Cstm Outb'!I10) -> NIL | P22: 总共： | R22: ='Cstm Outb'!D8+'Cstm Outb'!E8*2 -> 0 | T22: TEU | V22: ， | W22: 8256.5 | X22: 吨；
E23: 过境柜： | F23: ='Gen Inb'!F23 -> 20F×133, 40F×324 | P23: 总共： | R23: ='Gen Inb'!R23 -> 781 | T23: TEU | V23: ， | W23: ='Gen Inb'!W23 -> 9140 | X23: 吨；
B24: 14.船员人数(含船长) | H24: 17 | I24: 15.旅客人数 | N24: ='Gen Inb'!N24 -> nil | O24: 16.备 注 | R24: 无武器 | W24: 船员国籍分布：
B25: Number of crew(incl. Master) | I25: Number of Passengers | O25: Remarks | R25: No Weapen | W25: 菲律宾11名
B26: 附件(标明份数) | O26: 船舶呼号： | R26: V2CO6 | W26: 乌克兰2名
B27: Attached documents(indicate number of copies) | O27: MMSI： | R27: 305060000 | W27: 俄罗斯4名
B28: 17.货物申报单 | I28: 18.船用物品申报单 | O28: 船公司： | R28: 德翔航运
B29: Cargo Declaration | I29: Ship's Stord Declaration | O29: 航次：进/出 | R29: 20024SI/20024S
B30: 19.船员名单. | H30: 1 | I30: 20.旅客名单 | N30: nil | O30: 21.船长或其代理人签名、日期
B31: Crew List | I31: Passenger List | O31: Date and signature by master,authorized agent or officer
B32: 22.船员物品申报单* | I32: 23.航海健康申报书
B33: Crew's Effects Declaration | I33: Maritime Declaration of Health
B34: 检查机关签注
B35: For official use

Sheet Cgo Outb
A1: IMO Convention on Facilitation of International Maritime Traffic | B1: 货 物 申 报 单
B2: CARGO DECLARATION
B3: 编号 | E3: 抵港 | F3: 离港 | G3: 第 页
B4: No. | E4: Arrival | F4: Departure | G4: Page No.
B6: 1. 船 名 | C6: ='Gen Inb'!I6 -> 马士基奋进 | F6: 2. 申报港 | G6: ='Gen Outb'!S6 -> 南沙新港
B7: Name of ship | C7: ='Gen Inb'!I7 -> ERASMUS EFFORT | F7: Port where report is made | G7: ='Gen Outb'!S7 -> NANSHA NEW PORT
B8: 3. 船舶国籍 | C8: ='Gen Outb'!F8 -> 巴拿马 | D8: 4. 船长姓名 | E8: ='Gen Inb'!M8 -> 李继祥 | F8: 5. 装卸港 | G8: ='Gen Outb'!S6 -> 南沙新港
B9: Nationality of ship | C9: ='Gen Outb'!F9 -> PANAMA | D9: Name of master | F9: Port of loading/Port of discharge | G9: ='Gen Outb'!S7 -> NANSHA NEW PORT
B10: 6. 标记及号码 | C10: 7. 包件的种类和数量 | F10: 8. 毛 重 | G10: 9. 单 位
B11: Marks and Nos. | C11: Number and kind of packages, description of goods | F11: Gross weight | G11: measurement
D15: ='Gen Outb'!J21&'Gen Outb'!M21&" "&'Gen Outb'!O21 -> 总重量：17396.5 吨
J16: P
C17: ='Gen Outb'!E22&'Gen Outb'!F22 -> 出口柜：NIL
D18: ='Gen Outb'!P22&'Gen Outb'!R22&" "&'Gen Outb'!T22&'Gen Outb'!V22&'Gen Outb'!W22&" "&'Gen Outb'!X22 -> 总共：0 TEU，8256.5 吨；
C19: ='Gen Inb'!E23&'Gen Inb'!F23 -> 过境柜：20F×133, 40F×324
D20: ='Gen Inb'!P23&'Gen Inb'!R23&" "&'Gen Inb'!T23&'Gen Inb'!V23&'Gen Inb'!W23&" "&'Gen Inb'!X23 -> 总共：781 TEU，9140 吨；
C26: ='Gen Inb'!P12&"："&'Gen Inb'!V12 -> ：
D27: ='Gen Inb'!V14 -> 0
B34: 10. 船长或其代理人签名、日期
B35: Date and signature by master, authorized agent or officer
F37: 中华人民共和国海事局监制
F38: 98版本 仿造必究

Sheet Crew Inb
A1: IMO CREW LIST
K2: Page No.
K3: 1 of 1
B5: 1.1 Name and type of ship | D5: ='Gen Inb'!I7 -> ERASMUS EFFORT | F5: ='Gen Inb'!M7 -> Container | G5: 2. Port of arrival/departure | J5: 3. Date of arrival/departure
B6: 1.2 IMO number | D6: ='Gen Inb'!I10 -> IMO:1032452 | G6: ='Gen Inb'!S7 -> NANSHA NEW PORT | J6: ='Gen Inb'!X6 -> 46238
B7: 1.3 Call sign | D7: ='Gen Inb'!R26 -> 3E8968
B8: 4. Flag state of ship | G8: 5. Last port of call | J8: 11.1 Nature and No. of identity docment (seamen's passport)
B9: ='Gen Inb'!F9 -> PANAMA | G9: ='Gen Inb'!W9 -> HO CHI MINH CITY
B10: 6. No | C10: 7.1 Family name, given names | E10: 7.2 M/F | F10: 8. Rank or rating | G10: 9. Nationality | H10: 10. Date and place of birth
A11: IMO Convention of Facilitation of International Maritime Traffic | B11: =IF(C11<>"",COUNTA(C$11:C11),"") -> 1 | C11: 李继祥 | E11: M | F11: Master | G11: Montenegro | H11: 29228 | I11: Montenegro | J11: P | K11: B42BR8005 | L11: 名单版本是正确的
B12: =IF(C12<>"",COUNTA(C$11:C12),"") -> 2 | C12: FERNANDEZ REYNALDO JR | E12: M | F12: Chief Officer | G12: Ukraine | H12: 24515 | I12: Ukraine | J12: S | K12: AB498691
B13: =IF(C13<>"",COUNTA(C$11:C13),"") -> 3 | C13: FERNANDEZ REYNALDO JR | E13: M | F13: Second Officer | G13: Filipino | H13: 29167 | I13: Filipino | J13: P | K13: P0392496A
B14: =IF(C14<>"",COUNTA(C$11:C14),"") -> 4 | C14: GONZAGA JOHN BRIAN CANALITA | E14: M | F14: Third Officer | G14: Filipino | H14: 34095 | I14: Filipino | J14: P | K14: EC3697674
B15: =IF(C15<>"",COUNTA(C$11:C15),"") -> 5 | C15: DYACHENKO VASYL | E15: M | F15: Chief Engineer | G15: Ukraine | H15: 27961 | I15: Ukraine | J15: S | K15: AB406216
B16: =IF(C16<>"",COUNTA(C$11:C16),"") -> 6 | C16: BALAKIN OLEG | E16: M | F16: Second Engineer | G16: Ukraine | H16: 24595 | I16: Ukraine | J16: S | K16: AB565162
B17: =IF(C17<>"",COUNTA(C$11:C17),"") -> 7 | C17: BACERDO OMAR DAMES | E17: M | F17: Junior Engineer | G17: Filipino | H17: 34157 | I17: Filipino | J17: P | K17: P1649209A
B18: =IF(C18<>"",COUNTA(C$11:C18),"") -> 8 | C18: SANTACERA ROTSEN MAR DAYADAY | E18: M | F18: Junior Electrician | G18: Filipino | H18: 32956 | I18: Filipino | J18: P | K18: P1399821A
B19: =IF(C19<>"",COUNTA(C$11:C19),"") -> 9 | C19: JAVIER EDGAR AMMEN | E19: M | F19: Bosun | G19: Filipino | H19: 25430 | I19: Filipino | J19: P | K19: EC4641553
B20: =IF(C20<>"",COUNTA(C$11:C20),"") -> 10 | C20: ELPA KENNETH BLANCO | E20: M | F20: Able Seaman | G20: Filipino | H20: 29746 | I20: Filipino | J20: P | K20: P2512380A
B21: =IF(C21<>"",COUNTA(C$11:C21),"") -> 11 | C21: FLORENTINO JOEMARIE LACHICA | E21: M | F21: Able Seaman | G21: Filipino | H21: 28234 | I21: Filipino | J21: P | K21: EC6525043
B22: =IF(C22<>"",COUNTA(C$11:C22),"") -> 12 | C22: SUAREZ JETTE ANTHONY CAPANAS | E22: M | F22: Able Seaman | G22: Filipino | H22: 30471 | I22: Filipino | J22: P | K22: P0863919A
B23: =IF(C23<>"",COUNTA(C$11:C23),"") -> 13 | C23: JAMERO IANJAY HAMOAY | E23: M | F23: Ordinary Seaman | G23: Filipino | H23: 30822 | I23: Filipino | J23: P | K23: EC5956980
... B30: =IF(C30<>"",COUNTA(C$11:C30),"") -> 20 | C30: CAMANAY JONATHAN SUAZO | E30: M | F30: Messboy | G30: Filipino | H30: 31563 | I30: Filipino | J30: P | K30: EC8290337
B31: 12. Date and signature by master, authorized by agent or officer
B32: Signed | I32: Date
B34: IMO FAL
B35: Form 5
B36: C97

Sheet Immi In
A1: 证件号码 | B1: 证件类别 | C1: 国籍地区 | D1: 姓名 | E1: 性别 | F1: 出生日期 | G1: 职务 | H1: 签证种类 | I1: 有效期 | J1: 入出境事由 | K1: 人员类别
A2: =IF('Crew Inb'!K11="","",'Crew Inb'!K11) -> B42BR8005 | B2: =IF('Crew Inb'!J11="","",IF('Crew Inb'!J11="P","普通护照",IF('Crew Inb'!J11="S","海员证",""))) -> 普通护照 | C2: 印度 | D2: =IF('Crew Inb'!C11="","",'Crew Inb'!C11&" "&'Crew Inb'!D11) -> 李继祥 | E2: =IF('Crew Inb'!E11="","",IF('Crew Inb'!E11="M","男",IF('Crew Inb'!E11="F","女","未说明"))) -> 男 | F2: =IF('Crew Inb'!H11="","",'Crew Inb'!H11) -> 29228 | G2: 船长 | H2: =IF('Crew Inb'!C11="","","免办签证") -> 免办签证
A3: =IF('Crew Inb'!K12="","",'Crew Inb'!K12) -> AB498691 | B3: =IF('Crew Inb'!J12="","",IF('Crew Inb'!J12="P","普通护照",IF('Crew Inb'!J12="S","海员证",""))) -> 海员证 | C3: 菲律宾 | D3: =IF('Crew Inb'!C12="","",'Crew Inb'!C12&" "&'Crew Inb'!D12) -> FERNANDEZ REYNALDO JR | E3: =IF('Crew Inb'!E12="","",IF('Crew Inb'!E12="M","男",IF('Crew Inb'!E12="F","女","未说明"))) -> 男 | F3: =IF('Crew Inb'!H12="","",'Crew Inb'!H12) -> 24515 | G3: 大副 | H3: =IF('Crew Inb'!C12="","","免办签证") -> 免办签证
A4: =IF('Crew Inb'!K13="","",'Crew Inb'!K13) -> P0392496A | B4: =IF('Crew Inb'!J13="","",IF('Crew Inb'!J13="P","普通护照",IF('Crew Inb'!J13="S","海员证",""))) -> 普通护照 | C4: 缅甸 | D4: =IF('Crew Inb'!C13="","",'Crew Inb'!C13&" "&'Crew Inb'!D13) -> FERNANDEZ REYNALDO JR | E4: =IF('Crew Inb'!E13="","",IF('Crew Inb'!E13="M","男",IF('Crew Inb'!E13="F","女","未说明"))) -> 男 | F4: =IF('Crew Inb'!H13="","",'Crew Inb'!H13) -> 29167 | G4: 二副 | H4: =IF('Crew Inb'!C13="","","免办签证") -> 免办签证
A5: =IF('Crew Inb'!K14="","",'Crew Inb'!K14) -> EC3697674 | B5: =IF('Crew Inb'!J14="","",IF('Crew Inb'!J14="P","普通护照",IF('Crew Inb'!J14="S","海员证",""))) -> 普通护照 | C5: 印度 | D5: =IF('Crew Inb'!C14="","",'Crew Inb'!C14&" "&'Crew Inb'!D14) -> GONZAGA JOHN BRIAN CANALITA | E5: =IF('Crew Inb'!E14="","",IF('Crew Inb'!E14="M","男",IF('Crew Inb'!E14="F","女","未说明"))) -> 男 | F5: =IF('Crew Inb'!H14="","",'Crew Inb'!H14) -> 34095 | G5: 三副 | H5: =IF('Crew Inb'!C14="","","免办签证") -> 免办签证
A6: =IF('Crew Inb'!K15="","",'Crew Inb'!K15) -> AB406216 | B6: =IF('Crew Inb'!J15="","",IF('Crew Inb'!J15="P","普通护照",IF('Crew Inb'!J15="S","海员证",""))) -> 海员证 | C6: 菲律宾 | D6: =IF('Crew Inb'!C15="","",'Crew Inb'!C15&" "&'Crew Inb'!D15) -> DYACHENKO VASYL | E6: =IF('Crew Inb'!E15="","",IF('Crew Inb'!E15="M","男",IF('Crew Inb'!E15="F","女","未说明"))) -> 男 | F6: =IF('Crew Inb'!H15="","",'Crew Inb'!H15) -> 27961 | G6: 甲板实习生 | H6: =IF('Crew Inb'!C15="","","免办签证") -> 免办签证
A7: =IF('Crew Inb'!K16="","",'Crew Inb'!K16) -> AB565162 | B7: =IF('Crew Inb'!J16="","",IF('Crew Inb'!J16="P","普通护照",IF('Crew Inb'!J16="S","海员证",""))) -> 海员证 | C7: 菲律宾 | D7: =IF('Crew Inb'!C16="","",'Crew Inb'!C16&" "&'Crew Inb'!D16) -> BALAKIN OLEG | E7: =IF('Crew Inb'!E16="","",IF('Crew Inb'!E16="M","男",IF('Crew Inb'!E16="F","女","未说明"))) -> 男 | F7: =IF('Crew Inb'!H16="","",'Crew Inb'!H16) -> 24595 | G7: 轮机长 | H7: =IF('Crew Inb'!C16="","","免办签证") -> 免办签证
A8: =IF('Crew Inb'!K17="","",'Crew Inb'!K17) -> P1649209A | B8: =IF('Crew Inb'!J17="","",IF('Crew Inb'!J17="P","普通护照",IF('Crew Inb'!J17="S","海员证",""))) -> 普通护照 | C8: 中国 | D8: =IF('Crew Inb'!C17="","",'Crew Inb'!C17&" "&'Crew Inb'!D17) -> BACERDO OMAR DAMES | E8: =IF('Crew Inb'!E17="","",IF('Crew Inb'!E17="M","男",IF('Crew Inb'!E17="F","女","未说明"))) -> 男 | F8: =IF('Crew Inb'!H17="","",'Crew Inb'!H17) -> 34157 | G8: 大管轮 | H8: =IF('Crew Inb'!C17="","","免办签证") -> 免办签证
A9: =IF('Crew Inb'!K18="","",'Crew Inb'!K18) -> P1399821A | B9: =IF('Crew Inb'!J18="","",IF('Crew Inb'!J18="P","普通护照",IF('Crew Inb'!J18="S","海员证",""))) -> 普通护照 | C9: 乌克兰 | D9: =IF('Crew Inb'!C18="","",'Crew Inb'!C18&" "&'Crew Inb'!D18) -> SANTACERA ROTSEN MAR DAYADAY | E9: =IF('Crew Inb'!E18="","",IF('Crew Inb'!E18="M","男",IF('Crew Inb'!E18="F","女","未说明"))) -> 男 | F9: =IF('Crew Inb'!H18="","",'Crew Inb'!H18) -> 32956 | G9: 二管轮 | H9: =IF('Crew Inb'!C18="","","免办签证") -> 免办签证
A10: =IF('Crew Inb'!#REF!="","",'Crew Inb'!#REF!) -> #REF! | B10: =IF('Crew Inb'!#REF!="","",IF('Crew Inb'!#REF!="P","普通护照",IF('Crew Inb'!#REF!="S","海员证",""))) -> #REF! | C10: 巴基斯坦 | D10: =IF('Crew Inb'!#REF!="","",'Crew Inb'!#REF!&" "&'Crew Inb'!#REF!) -> #REF! | E10: =IF('Crew Inb'!#REF!="","",IF('Crew Inb'!#REF!="M","男",IF('Crew Inb'!#REF!="F","女","未说明"))) -> #REF! | F10: =IF('Crew Inb'!#REF!="","",'Crew Inb'!#REF!) -> #REF! | G10: 三管轮 | H10: =IF('Crew Inb'!#REF!="","","免办签证") -> #REF!
A11: =IF('Crew Inb'!K19="","",'Crew Inb'!K19) -> EC4641553 | B11: =IF('Crew Inb'!J19="","",IF('Crew Inb'!J19="P","普通护照",IF('Crew Inb'!J19="S","海员证",""))) -> 普通护照 | C11: 印度 | D11: =IF('Crew Inb'!C19="","",'Crew Inb'!C19&" "&'Crew Inb'!D19) -> JAVIER EDGAR AMMEN | E11: =IF('Crew Inb'!E19="","",IF('Crew Inb'!E19="M","男",IF('Crew Inb'!E19="F","女","未说明"))) -> 男 | F11: =IF('Crew Inb'!H19="","",'Crew Inb'!H19) -> 25430 | G11: 电工 | H11: =IF('Crew Inb'!C19="","","免办签证") -> 免办签证
A12: =IF('Crew Inb'!K20="","",'Crew Inb'!K20) -> P2512380A | B12: =IF('Crew Inb'!J20="","",IF('Crew Inb'!J20="P","普通护照",IF('Crew Inb'!J20="S","海员证",""))) -> 普通护照 | C12: 孟加拉国 | D12: =IF('Crew Inb'!C20="","",'Crew Inb'!C20&" "&'Crew Inb'!D20) -> ELPA KENNETH BLANCO | E12: =IF('Crew Inb'!E20="","",IF('Crew Inb'!E20="M","男",IF('Crew Inb'!E20="F","女","未说明"))) -> 男 | F12: =IF('Crew Inb'!H20="","",'Crew Inb'!H20) -> 29746 | G12: 铜匠 | H12: =IF('Crew Inb'!C20="","","免办签证") -> 免办签证
A13: =IF('Crew Inb'!K21="","",'Crew Inb'!K21) -> EC6525043 | B13: =IF('Crew Inb'!J21="","",IF('Crew Inb'!J21="P","普通护照",IF('Crew Inb'!J21="S","海员证",""))) -> 普通护照 | C13: 斯里兰卡 | D13: =IF('Crew Inb'!C21="","",'Crew Inb'!C21&" "&'Crew Inb'!D21) -> FLORENTINO JOEMARIE LACHICA | E13: =IF('Crew Inb'!E21="","",IF('Crew Inb'!E21="M","男",IF('Crew Inb'!E21="F","女","未说明"))) -> 男 | F13: =IF('Crew Inb'!H21="","",'Crew Inb'!H21) -> 28234 | G13: 水手长 | H13: =IF('Crew Inb'!C21="","","免办签证") -> 免办签证
A14: =IF('Crew Inb'!K22="","",'Crew Inb'!K22) -> P0863919A | B14: =IF('Crew Inb'!J22="","",IF('Crew Inb'!J22="P","普通护照",IF('Crew Inb'!J22="S","海员证",""))) -> 普通护照 | C14: 印度 | D14: =IF('Crew Inb'!C22="","",'Crew Inb'!C22&" "&'Crew Inb'!D22) -> SUAREZ JETTE ANTHONY CAPANAS | E14: =IF('Crew Inb'!E22="","",IF('Crew Inb'!E22="M","男",IF('Crew Inb'!E22="F","女","未说明"))) -> 男 | F14: =IF('Crew Inb'!H22="","",'Crew Inb'!H22) -> 30471 | G14: 一水 | H14: =IF('Crew Inb'!C22="","","免办签证") -> 免办签证
A15: =IF('Crew Inb'!K23="","",'Crew Inb'!K23) -> EC5956980 | B15: =IF('Crew Inb'!J23="","",IF('Crew Inb'!J23="P","普通护照",IF('Crew Inb'!J23="S","海员证",""))) -> 普通护照 | C15: 印度 | D15: =IF('Crew Inb'!C23="","",'Crew Inb'!C23&" "&'Crew Inb'!D23) -> JAMERO IANJAY HAMOAY | E15: =IF('Crew Inb'!E23="","",IF('Crew Inb'!E23="M","男",IF('Crew Inb'!E23="F","女","未说明"))) -> 男 | F15: =IF('Crew Inb'!H23="","",'Crew Inb'!H23) -> 30822 | G15: 一水 | H15: =IF('Crew Inb'!C23="","","免办签证") -> 免办签证
A16: =IF('Crew Inb'!K24="","",'Crew Inb'!K24) -> P3925249A | B16: =IF('Crew Inb'!J24="","",IF('Crew Inb'!J24="P","普通护照",IF('Crew Inb'!J24="S","海员证",""))) -> 普通护照 | C16: 印度 | D16: =IF('Crew Inb'!C24="","",'Crew Inb'!C24&" "&'Crew Inb'!D24) -> PELLETERO ALLEN SEGISMUNDO | E16: =IF('Crew Inb'!E24="","",IF('Crew Inb'!E24="M","男",IF('Crew Inb'!E24="F","女","未说明"))) -> 男 | F16: =IF('Crew Inb'!H24="","",'Crew Inb'!H24) -> 33702 | G16: 一水 | H16: =IF('Crew Inb'!C24="","","免办签证") -> 免办签证
A17: =IF('Crew Inb'!K25="","",'Crew Inb'!K25) -> EC4389049 | B17: =IF('Crew Inb'!J25="","",IF('Crew Inb'!J25="P","普通护照",IF('Crew Inb'!J25="S","海员证",""))) -> 普通护照 | C17: 印度 | D17: =IF('Crew Inb'!C25="","",'Crew Inb'!C25&" "&'Crew Inb'!D25) -> OLOJAN ROSEN JUANICO | E17: =IF('Crew Inb'!E25="","",IF('Crew Inb'!E25="M","男",IF('Crew Inb'!E25="F","女","未说明"))) -> 男 | F17: =IF('Crew Inb'!H25="","",'Crew Inb'!H25) -> 24553 | G17: 二水 | H17: =IF('Crew Inb'!C25="","","免办签证") -> 免办签证
A18: =IF('Crew Inb'!K26="","",'Crew Inb'!K26) -> P2263420A | B18: =IF('Crew Inb'!J26="","",IF('Crew Inb'!J26="P","普通护照",IF('Crew Inb'!J26="S","海员证",""))) -> 普通护照 | C18: 印度 | D18: =IF('Crew Inb'!C26="","",'Crew Inb'!C26&" "&'Crew Inb'!D26) -> CAMILOTE GEOFFREY CALETINA | E18: =IF('Crew Inb'!E26="","",IF('Crew Inb'!E26="M","男",IF('Crew Inb'!E26="F","女","未说明"))) -> 男 | F18: =IF('Crew Inb'!H26="","",'Crew Inb'!H26) -> 28098 | G18: 二水 | H18: =IF('Crew Inb'!C26="","","免办签证") -> 免办签证
A19: =IF('Crew Inb'!K27="","",'Crew Inb'!K27) -> P3596511A | B19: =IF('Crew Inb'!J27="","",IF('Crew Inb'!J27="P","普通护照",IF('Crew Inb'!J27="S","海员证",""))) -> 普通护照 | C19: 印度 | D19: =IF('Crew Inb'!C27="","",'Crew Inb'!C27&" "&'Crew Inb'!D27) -> ECAT JOSEPH PAUL TENEBRO | E19: =IF('Crew Inb'!E27="","",IF('Crew Inb'!E27="M","男",IF('Crew Inb'!E27="F","女","未说明"))) -> 男 | F19: =IF('Crew Inb'!H27="","",'Crew Inb'!H27) -> 34260 | G19: 二水 | H19: =IF('Crew Inb'!C27="","","免办签证") -> 免办签证
A20: =IF('Crew Inb'!#REF!="","",'Crew Inb'!#REF!) -> #REF! | B20: =IF('Crew Inb'!#REF!="","",IF('Crew Inb'!#REF!="P","普通护照",IF('Crew Inb'!#REF!="S","海员证",""))) -> #REF! | C20: 印度 | D20: =IF('Crew Inb'!#REF!="","",'Crew Inb'!#REF!&" "&'Crew Inb'!#REF!) -> #REF! | E20: =IF('Crew Inb'!#REF!="","",IF('Crew Inb'!#REF!="M","男",IF('Crew Inb'!#REF!="F","女","未说明"))) -> #REF! | F20: =IF('Crew Inb'!#REF!="","",'Crew Inb'!#REF!) -> #REF! | G20: 铜匠 | H20: =IF('Crew Inb'!#REF!="","","免办签证") -> #REF!
A21: =IF('Crew Inb'!#REF!="","",'Crew Inb'!#REF!) -> #REF! | B21: =IF('Crew Inb'!#REF!="","",IF('Crew Inb'!#REF!="P","普通护照",IF('Crew Inb'!#REF!="S","海员证",""))) -> #REF! | C21: 印度 | D21: =IF('Crew Inb'!#REF!="","",'Crew Inb'!#REF!&" "&'Crew Inb'!#REF!) -> #REF! | E21: =IF('Crew Inb'!#REF!="","",IF('Crew Inb'!#REF!="M","男",IF('Crew Inb'!#REF!="F","女","未说明"))) -> #REF! | F21: =IF('Crew Inb'!#REF!="","",'Crew Inb'!#REF!) -> #REF! | G21: 加油 | H21: =IF('Crew Inb'!#REF!="","","免办签证") -> #REF!
A22: =IF('Crew Inb'!#REF!="","",'Crew Inb'!#REF!) -> #REF! | B22: =IF('Crew Inb'!#REF!="","",IF('Crew Inb'!#REF!="P","普通护照",IF('Crew Inb'!#REF!="S","海员证",""))) -> #REF! | C22: 印度 | D22: =IF('Crew Inb'!#REF!="","",'Crew Inb'!#REF!&" "&'Crew Inb'!#REF!) -> #REF! | E22: =IF('Crew Inb'!#REF!="","",IF('Crew Inb'!#REF!="M","男",IF('Crew Inb'!#REF!="F","女","未说明"))) -> #REF! | F22: =IF('Crew Inb'!#REF!="","",'Crew Inb'!#REF!) -> #REF! | G22: 抹油 | H22: =IF('Crew Inb'!#REF!="","","免办签证") -> #REF!
A23: =IF('Crew Inb'!#REF!="","",'Crew Inb'!#REF!) -> #REF! | B23: =IF('Crew Inb'!#REF!="","",IF('Crew Inb'!#REF!="P","普通护照",IF('Crew Inb'!#REF!="S","海员证",""))) -> #REF! | C23: 印度 | D23: =IF('Crew Inb'!#REF!="","",'Crew Inb'!#REF!&" "&'Crew Inb'!#REF!) -> #REF! | E23: =IF('Crew Inb'!#REF!="","",IF('Crew Inb'!#REF!="M","男",IF('Crew Inb'!#REF!="F","女","未说明"))) -> #REF! | F23: =IF('Crew Inb'!#REF!="","",'Crew Inb'!#REF!) -> #REF! | G23: 抹油 | H23: =IF('Crew Inb'!#REF!="","","免办签证") -> #REF!
A24: =IF('Crew Inb'!#REF!="","",'Crew Inb'!#REF!) -> #REF! | B24: =IF('Crew Inb'!#REF!="","",IF('Crew Inb'!#REF!="P","普通护照",IF('Crew Inb'!#REF!="S","海员证",""))) -> #REF! | C24: 印度 | D24: =IF('Crew Inb'!#REF!="","",'Crew Inb'!#REF!&" "&'Crew Inb'!#REF!) -> #REF! | E24: =IF('Crew Inb'!#REF!="","",IF('Crew Inb'!#REF!="M","男",IF('Crew Inb'!#REF!="F","女","未说明"))) -> #REF! | F24: =IF('Crew Inb'!#REF!="","",'Crew Inb'!#REF!) -> #REF! | G24: 抹油 | H24: =IF('Crew Inb'!#REF!="","","免办签证") -> #REF!
A25: =IF('Crew Inb'!#REF!="","",'Crew Inb'!#REF!) -> #REF! | B25: =IF('Crew Inb'!#REF!="","",IF('Crew Inb'!#REF!="P","普通护照",IF('Crew Inb'!#REF!="S","海员证",""))) -> #REF! | C25: 印度 | D25: =IF('Crew Inb'!#REF!="","",'Crew Inb'!#REF!&" "&'Crew Inb'!#REF!) -> #REF! | E25: =IF('Crew Inb'!#REF!="","",IF('Crew Inb'!#REF!="M","男",IF('Crew Inb'!#REF!="F","女","未说明"))) -> #REF! | F25: =IF('Crew Inb'!#REF!="","",'Crew Inb'!#REF!) -> #REF! | G25: 抹油 | H25: =IF('Crew Inb'!#REF!="","","免办签证") -> #REF!
A26: =IF('Crew Inb'!#REF!="","",'Crew Inb'!#REF!) -> #REF! | B26: =IF('Crew Inb'!#REF!="","",IF('Crew Inb'!#REF!="P","普通护照",IF('Crew Inb'!#REF!="S","海员证",""))) -> #REF! | C26: 印度 | D26: =IF('Crew Inb'!#REF!="","",'Crew Inb'!#REF!&" "&'Crew Inb'!#REF!) -> #REF! | E26: =IF('Crew Inb'!#REF!="","",IF('Crew Inb'!#REF!="M","男",IF('Crew Inb'!#REF!="F","女","未说明"))) -> #REF! | F26: =IF('Crew Inb'!#REF!="","",'Crew Inb'!#REF!) -> #REF! | G26: 抹油 | H26: =IF('Crew Inb'!#REF!="","","免办签证") -> #REF!
A27: =IF('Crew Inb'!#REF!="","",'Crew Inb'!#REF!) -> #REF! | B27: =IF('Crew Inb'!#REF!="","",IF('Crew Inb'!#REF!="P","普通护照",IF('Crew Inb'!#REF!="S","海员证",""))) -> #REF! | C27: 印度 | D27: =IF('Crew Inb'!#REF!="","",'Crew Inb'!#REF!&" "&'Crew Inb'!#REF!) -> #REF! | E27: =IF('Crew Inb'!#REF!="","",IF('Crew Inb'!#REF!="M","男",IF('Crew Inb'!#REF!="F","女","未说明"))) -> #REF! | F27: =IF('Crew Inb'!#REF!="","",'Crew Inb'!#REF!) -> #REF! | G27: 抹油 | H27: =IF('Crew Inb'!#REF!="","","免办签证") -> #REF!
A28: =IF('Crew Inb'!#REF!="","",'Crew Inb'!#REF!) -> #REF! | B28: =IF('Crew Inb'!#REF!="","",IF('Crew Inb'!#REF!="P","普通护照",IF('Crew Inb'!#REF!="S","海员证",""))) -> #REF! | C28: 印度 | D28: =IF('Crew Inb'!#REF!="","",'Crew Inb'!#REF!&" "&'Crew Inb'!#REF!) -> #REF! | E28: =IF('Crew Inb'!#REF!="","",IF('Crew Inb'!#REF!="M","男",IF('Crew Inb'!#REF!="F","女","未说明"))) -> #REF! | F28: =IF('Crew Inb'!#REF!="","",'Crew Inb'!#REF!) -> #REF! | G28: 抹油 | H28: =IF('Crew Inb'!#REF!="","","免办签证") -> #REF!
A29: =IF('Crew Inb'!#REF!="","",'Crew Inb'!#REF!) -> #REF! | B29: =IF('Crew Inb'!#REF!="","",IF('Crew Inb'!#REF!="P","普通护照",IF('Crew Inb'!#REF!="S","海员证",""))) -> #REF! | C29: 菲律宾 | D29: =IF('Crew Inb'!#REF!="","",'Crew Inb'!#REF!&" "&'Crew Inb'!#REF!) -> #REF! | E29: =IF('Crew Inb'!#REF!="","",IF('Crew Inb'!#REF!="M","男",IF('Crew Inb'!#REF!="F","女","未说明"))) -> #REF! | F29: =IF('Crew Inb'!#REF!="","",'Crew Inb'!#REF!) -> #REF! | G29: 抹油 | H29: =IF('Crew Inb'!#REF!="","","免办签证") -> #REF!
A30: =IF('Crew Inb'!#REF!="","",'Crew Inb'!#REF!) -> #REF! | F30: =IF('Crew Inb'!#REF!="","",'Crew Inb'!#REF!) -> #REF!
A31: =IF('Crew Inb'!#REF!="","",'Crew Inb'!#REF!) -> #REF! | D31: =IF('Crew Inb'!#REF!="","",'Crew Inb'!#REF!&" "&'Crew Inb'!#REF!) -> #REF! | F31: =IF('Crew Inb'!#REF!="","",'Crew Inb'!#REF!) -> #REF!
A32: =IF('Crew Inb'!#REF!="","",'Crew Inb'!#REF!) -> #REF! | F32: =IF('Crew Inb'!#REF!="","",'Crew Inb'!#REF!) -> #REF!
A33: =IF('Crew Inb'!#REF!="","",'Crew Inb'!#REF!) -> #REF! | F33: =IF('Crew Inb'!#REF!="","",'Crew Inb'!#REF!) -> #REF!
A34: =IF('Crew Inb'!#REF!="","",'Crew Inb'!#REF!) -> #REF! | F34: =IF('Crew Inb'!#REF!="","",'Crew Inb'!#REF!) -> #REF!
A35: =IF('Crew Inb'!#REF!="","",'Crew Inb'!#REF!) -> #REF! | F35: =IF('Crew Inb'!#REF!="","",'Crew Inb'!#REF!) -> #REF!
A36: =IF('Crew Inb'!#REF!="","",'Crew Inb'!#REF!) -> #REF! | F36: =IF('Crew Inb'!#REF!="","",'Crew Inb'!#REF!) -> #REF!
A37: =IF('Crew Inb'!#REF!="","",'Crew Inb'!#REF!) -> #REF! | F37: =IF('Crew Inb'!#REF!="","",'Crew Inb'!#REF!) -> #REF!
A38: =IF('Crew Inb'!#REF!="","",'Crew Inb'!#REF!) -> #REF! | F38: =IF('Crew Inb'!#REF!="","",'Crew Inb'!#REF!) -> #REF!
A39: =IF('Crew Inb'!#REF!="","",'Crew Inb'!#REF!) -> #REF! | B39: =IF('Crew Inb'!#REF!="","",IF('Crew Inb'!#REF!="P","普通护照",IF('Crew Inb'!#REF!="S","海员证",""))) -> #REF! | D39: =IF('Crew Inb'!#REF!="","",'Crew Inb'!#REF!&" "&'Crew Inb'!#REF!) -> #REF! | F39: =IF('Crew Inb'!#REF!="","",'Crew Inb'!#REF!) -> #REF! | H39: =IF('Crew Inb'!#REF!="","","免办签证") -> #REF!
A40: =IF('Crew Inb'!#REF!="","",'Crew Inb'!#REF!) -> #REF! | B40: =IF('Crew Inb'!J31="","",IF('Crew Inb'!J31="P","普通护照",IF('Crew Inb'!J31="S","海员证",""))) | D40: =IF('Crew Inb'!C31="","",'Crew Inb'!C31&" "&'Crew Inb'!D31) | F40: =IF('Crew Inb'!#REF!="","",'Crew Inb'!#REF!) -> #REF! | H40: =IF('Crew Inb'!C31="","","免办签证")
...

Sheet Crew Dwn
B1: 船 员 更 动 报 告 单
B2: REPORT OF CREW REPLACEMENT
B4: 船 名 | D4: ='Gen Inb'!I6 -> 马士基奋进 | G4: 国 籍 | H4: ='Gen Inb'!F8 -> 巴拿马
B5: M.V. | D5: ='Gen Inb'!I7 -> ERASMUS EFFORT | G5: Nationality | H5: ='Gen Inb'!F9 -> PANAMA
B6: 姓 名 | D6: 国 籍 | E6: 出生日期 | F6: 职别 | G6: 护照/海员证字号 | H6: 更动原因
B7: Name of Replacement | D7: Nationality | E7: Date of Birth | F7: Rank | G7: Passport Number/ Seaman's Number | H7: Reason of Replacement
B8: MARIGON JUNE AGREDA | D8: 菲律宾 | E8: 29025 | F8: 轮机长 | G8: 护照/P4794223A | H8: 离船
G17: 船 长 签 名
B18: ='Gen Inb'!P12 -> 0 | G18: Signature of Master:
B19: Guangzhou Port Unitrans Agency Co., Ltd. | G19: 日 期 | H19: ='Gen Inb'!X6 -> 46238
G20: Date:

Sheet Crew Outb
A1: IMO CREW LIST
K2: Page No.
K3: 1 of 1
B5: 1.1 Name and type of ship | D5: ='Gen Inb'!I7 -> ERASMUS EFFORT | F5: ='Gen Inb'!M7 -> Container | G5: 2. Port of arrival/departure | J5: 3. Date of arrival/departure
B6: 1.2 IMO number | D6: ='Gen Inb'!I10 -> IMO:1032452 | G6: ='Gen Inb'!S7 -> NANSHA NEW PORT | J6: ='Gen Outb'!X6 -> 44160
B7: 1.3 Call sign | D7: ='Gen Inb'!R26 -> 3E8968
B8: 4. Flag state of ship | G8: 5. Last port of call | J8: 11.1 Nature and No. of identity docment (seamen's passport) | L8: 12.BODY TEMPERATURE
B9: ='Gen Inb'!F9 -> PANAMA | G9: ='Gen Inb'!W9 -> HO CHI MINH CITY
B10: 6. No | C10: 7.1 Family name, given names | E10: 7.2 M/F | F10: 8. Rank or rating | G10: 9. Nationality | H10: 10. Date and place of birth
A11: IMO Convention of Facilitation of International Maritime Traffic | B11: 1 | C11: BINKOVSKY ANDRIY | E11: M | F11: Master | G11: Montenegro | H11: 29228 | I11: Montenegro | J11: P | K11: B42BR8005
B12: 2 | C12: BILINS'KY ANDRIY | E12: M | F12: Chief Officer | G12: Ukraine | H12: 24515 | I12: Ukraine | J12: P | K12: ET549562
B13: 3 | C13: OGANA ROGELIO PENTON | E13: M | F13: Second Officer | G13: Filipino | H13: 29167 | I13: Filipino | J13: P | K13: P0392496A
B14: 4 | C14: GONZAGA JOHN BRIAN CANALITA | E14: M | F14: Third Officer | G14: Filipino | H14: 34095 | I14: Filipino | J14: P | K14: EC3697674
B15: 5 | C15: DIACHENKO VASYL | E15: M | F15: Chief Engineer | G15: Ukraine | H15: 27961 | I15: Ukraine | J15: P | K15: ET112764
B16: 6 | C16: BALAKIN OLEG | E16: M | F16: Second Engineer | G16: Ukraine | H16: 24595 | I16: Ukraine | J16: P | K16: ET529509
B17: 7 | C17: BACERDO OMAR DAMES | E17: M | F17: Junior Engineer | G17: Filipino | H17: 34157 | I17: Filipino | J17: P | K17: P1649209A
B18: 8 | C18: SANTACERA ROTSEN MAR DAYADAY | E18: M | F18: Junior Electrician | G18: Filipino | H18: 32956 | I18: Filipino | J18: P | K18: P1399821A
B19: 9 | C19: JAVIER EDGAR AMMEN | E19: M | F19: Bosun | G19: Filipino | H19: 25430 | I19: Filipino | J19: P | K19: EC4641553
B20: 10 | C20: ELPA KENNETH BLANCO | E20: M | F20: Able Seaman | G20: Filipino | H20: 29746 | I20: Filipino | J20: P | K20: P2512380A
B21: 11 | C21: FLORENTINO JOEMARIE LACHICA | E21: M | F21: Able Seaman | G21: Filipino | H21: 28234 | I21: Filipino | J21: P | K21: EC6525043
B22: 12 | C22: SUAREZ JETTE ANTHONY CAPANAS | E22: M | F22: Able Seaman | G22: Filipino | H22: 30471 | I22: Filipino | J22: P | K22: P0863919A
B23: 13 | C23: JAMERO IANJAY HAMOAY | E23: M | F23: Ordinary Seaman | G23: Filipino | H23: 30822 | I23: Filipino | J23: P | K23: EC5956980
... B30: 20 | C30: CAMANAY JONATHAN SUAZO | E30: M | F30: Messboy | G30: Filipino | H30: 31563 | I30: Filipino | J30: P | K30: EC8290337
B31: =IF(C31<>"",COUNTA(C$11:C31),"") -> 21 | C31: BILANGO JEAN CONSULAR | E31: F | F31: SUPERNUMERARY | G31: FILIPINO | H31: 23573 | I31: SAN MIGUEL BULACAN | J31: P | K31: EB9781010
B32: =IF(C32<>"",COUNTA(C$11:C32),"") | J32: =IF(C32="","","P")
B33: =IF(C33<>"",COUNTA(C$11:C33),"") | J33: =IF(C33="","","P")
B34: =IF(C34<>"",COUNTA(C$11:C34),"") | J34: =IF(C34="","","P")
B35: =IF(C35<>"",COUNTA(C$11:C35),"") | J35: =IF(C35="","","P")
B36: =IF(C36<>"",COUNTA(C$11:C36),"") | J36: =IF(C36="","","P")
B37: =IF(C37<>"",COUNTA(C$11:C37),"") | J37: =IF(C37="","","P")
B38: =IF(C38<>"",COUNTA(C$11:C38),"") | J38: =IF(C38="","","P")
B39: =IF(C39<>"",COUNTA(C$11:C39),"") | J39: =IF(C39="","","P")
B40: =IF(C40<>"",COUNTA(C$11:C40),"") | J40: =IF(C40="","","P")
B41: =IF(C41<>"",COUNTA(C$11:C41),"") | J41: =IF(C41="","","P")
B42: =IF(C42<>"",COUNTA(C$11:C42),"") | J42: =IF(C42="","","P")
B43: =IF(C43<>"",COUNTA(C$11:C43),"") | J43: =IF(C43="","","P")
... B45: =IF(C45<>"",COUNTA(C$11:C45),"") | J45: =IF(C45="","","P")
B46: 12. Date and signature by master, authorized by agent or officer
B47: Signed | I47: Date
B49: IMO FAL
...

Sheet Crew Up
B1: 船 员 更 动 报 告 单
B2: REPORT OF CREW REPLACEMENT
B4: 船 名 | D4: ='Gen Inb'!I6 -> 马士基奋进 | G4: 国 籍 | H4: ='Gen Inb'!F8 -> 巴拿马
B5: M.V. | D5: ='Gen Inb'!I7 -> ERASMUS EFFORT | G5: Nationality | H5: ='Gen Inb'!F9 -> PANAMA
B6: 姓 名 | D6: 国 籍 | E6: 出生日期 | F6: 职别 | G6: 护照/海员证字号 | H6: 更动原因
B7: Name of Replacement | D7: Nationality | E7: Date of Birth | F7: Rank | G7: Passport Number/ Seaman's Number | H7: Reason of Replacement
G17: 船 长 签 名
B18: ='Gen Inb'!P12 -> 0 | G18: Signature of Master:
B19: Guangzhou Port Unitrans Agency Co., Ltd. | G19: 日 期 | H19: ='Gen Outb'!X6 -> 44160
G20: Date:

Sheet Shore Pass
A1: APPLICATION FOR LANDING PERMIT
A3: TO: | B3: NANSHA | F3: Immigration Inspection Station
B5: There are | G5: crew members on board my ship in this
A7: voyage. Among them | I7: persons request to apply for landing
A9: permit.
B11: Ship's Name | J11: Captain's Signature
A13: ='Parts A'!B4 -> ERASMUS EFFORT
L16: ='Gen Inb'!X6 -> 46238
A17: ='Gen Inb'!P12 -> 0 | J17: Date

Sheet Health Dclr
C1: ENTRY-EXIT INSPECTION AND QUARANTINE OF THE PEOPLES REPUBLIC OF CHINA MERITIME DECLARATION OF HEALTH To be completed and submitted to the competent authorities of Inspection and Quarantine by the master of Entry-exit ships
A8: Submitted at the port of | G8: ='Gen Inb'!S7 -> NANSHA NEW PORT | N8: Date | P8: ='Gen Inb'!X6 -> 46238
A9: Name of ship or inland navigation vessel | L9: ='Gen Inb'!I7 -> ERASMUS EFFORT | O9: IMO No | R9: ='Gen Inb'!I10 -> IMO:1032452 | X9: Nationality | AB9: ='Gen Inb'!F9 -> PANAMA | AG9: Master's name | AI9: ='Gen Inb'!M8 -> 李继祥
A10: Entry ship:arriving from | G10: ='Gen Inb'!W9 -> HO CHI MINH CITY | Q10: Arrival date and time: | Y10: ='Gen Inb'!X6 -> 46238
A11: Exit ship:sailing to | E11: ='Gen Outb'!W9 -> HO CHI MINH CITY | Q11: Departure date and time: | Z11: 43783
A12: Gross tonnage(ship) | F12: ='Gen Inb'!E12 -> 9562 | H12: Is there ballasting water on board? Yes | Y12: Any radioactive cargo on board? Yes
S13: √ | V13: No | AL13: No | AM13: √
A15: food and drinking water loading ports? | N15: SINGAPORE
A16: Valid Sanitation Control Exemption/Control Certificate carried on board? Yes | Y16: No | AB16: Issued at | AI16: date
W17: √
A19: Has ship/vessel visited an affected area identified by the World Health Organization? Yes | AC19: No | AG19: If yes, Port and date of visit
AE20: √
A23: List ports of call from commencement of voyage with dates of departure,or within past four weeks,whichever is shorter:
A24: As Per ATTACHED PORT OF CALL ATTACHED
A26: Upon request of the competent authority at the port of arrival,list crew members,passengers or other persons who have joined ship/ves
A27: sel since international voyage began or within past four weeks,whichever is shorter,including all port/countries visited in this period
A28: (add additional names to the attached schedule):
A29: (1) | B29: Name | D29: NIL | I29: joined from:① | M29: NIL | R29: ② | T29: NIL | Z29: ③ | AB29: NIL
A30: (2) | B30: Name | D30: NIL | I30: joined from:① | M30: NIL | R30: ② | T30: NIL | Z30: ③ | AB30: NIL
A31: (3) | B31: Name | D31: NIL | I31: joined from:① | M31: NIL | R31: ② | T31: NIL | Z31: ③ | AB31: NIL
A32: Number of crew members on board | J32: ='Gen Outb'!H24 -> 17 | M32: Number of passengers on board | X32: NIL
A34: Health questions
A36: (1) | B36: Has any person died on board during the voyage otherwise than as a result of accident? | AI36: Yes | AM36: No
AO37: √
B39: If yes,state particulars in attached schedule. Total No. of deaths | Z39: .
A40: (2) | B40: Is there on board or has there been during the international voyage any case of disease | AI40: Yes | AM40: No
AO41: √
B43: which you suspect to be of an infectious nature?
B44: If yes,state particulars in attached schedule.
A45: (3) | B45: Has the total number of ill passengers during the voyage been greater than normal/expected? | AI45: Yes | AM45: No
AO46: √
B48: How many ill persons? | M48: person(s)
A49: (4) | B49: Is there any ill person on board now? | AI49: Yes | AM49: No
AO50: √
B52: If yes,state particulars in attached schedule.
A53: (5) | B53: Was a medical practitioner consulted? | AI53: Yes | AM53: No
AO54: √
A56: (6) | B56: If yes,state particulars of medical treatment or advice provided in attached schedule.
B57: Are you aware of any vondition on board which may lead to infection or spread of disease? | AI57: Yes | AM57: No
AO58: √
...

Sheet Parts A
B3: 马士基奋进 | E3: 巴拿马 | G3: 2007 | J3: 集装箱轮
B4: ERASMUS EFFORT | E4: PANAMA | J4: Container
B5: IMO:1032452 | E5: 9562 | G5: 4523 | J5: 10086/782
B6: 3E8968 | E6: 142 | G6: 22.6 | J6: 11.2
B7: 44 | E7: 8.2 | G7: 180 | J7: 740 KW
E8: 1 | G8: TS LINE
C10: 42727 | D10: 42908 | H10: 41575 | I10: N/A | J10: N/A
C11: 39776 | D11: N/A
C12: 41596 | D12: 43456 | E12: 42747
C13: 41596 | D13: 43456 | E13: 42747
C14: 42797 | D14: 43456 | E14: 42747 | H14: 42745 | I14: 43151
C15: 41596 | D15: 43456 | E15: 42747 | H15: 42262 | I15: 42858 | J15: 42507
C16: 41596 | D16: 43456 | E16: 42747 | H16: 42712 | I16: 42894
C17: N/A | H17: 42712 | I17: 42894
C18: N/A | I18: 28
C19: N/A | H19: SSCEC | I19: 42654 | J19: PORT KLANG
C21: 998959 | E21: 43549 | H21: 1050189 | J21: 44297
C22: 1047976 | E22: 44388 | H22: 1048985 | J22: 44442
C23: 1049874 | E23: 44481 | H23: 1049867 | J23: 44353
C24: 1049872 | E24: 44221
C25: 998959 | E25: 43549 | H25: 1049874 | J25: 44481
C27: YES | F27: 42315 | H27: Cotonou | J27: NO

Sheet Blst Wtr
D1: 中 华 人 民 共 和 国 出 入 境 检 验 检 疫
C2: ENTRY-EXIT INSPECTION AND QUARANTINE OF THE PEOPLE'S REPUBLIC OF CHINA
F4: 压 舱 水 申 报 单
E5: BALLAST WATER REPORTING FORM
A8: 船名 | B8: ='Gen Inb'!I6 -> 马士基奋进 | D8: 国籍 | E8: ='Gen Inb'!F8 -> 巴拿马 | H8: 到达港口 | J8: ='Gen Inb'!S6 -> 南沙新港 | L8: 到达日期 | M8: ='Gen Inb'!X6 -> 46238
A9: Name of Ship | B9: ='Gen Inb'!I7 -> ERASMUS EFFORT | D9: Nationality | E9: ='Gen Inb'!F9 -> PANAMA | H9: Arrival Port | J9: ='Gen Inb'!S7 -> NANSHA NEW PORT | L9: Arrival Date
A11: 船舶所有人 | B11: ='Parts A'!G8 -> TS LINE | D11: 船舶代理人 | E11: ='Gen Inb'!P12 -> 0 | H11: 压舱水总量（吨） | K11: =J23+J24+J25+J26+J27+J28 -> 1806 | L11: 压舱水池总数 | N11: 20
A12: Manager | D12: Agent | H12: Total Ballast on Board (tonnes) | L12: Total Number of Ballast Tanks
A14: 是否需要在中国某一港口排放压舱水？ | I14: 是 Yes
A15: Do you intend discharging any ballast water in a Chinese port? | I15: 否 No
A16: 压舱水箱/舱 Ballast Tanks/ Holds | B16: 压舱水来源 BW Source | E16: 压舱水更换(最近三次) BW Exchange (Last Three Exchange) 使用方法 Method used：清空 Empty / 灌注 Refill □ / 灌流 Flow Through □ | L16: 预计在中国港口排放压舱水情况 Best Estimate of BW Discharge in Chinese Ports
B19: 装载日期 Date of Uptake | C19: 装载地点 Location of Uptake | D19: 装载量(吨) Vol.taken Up(tons) | E19: 更换日期 Date of Exchange | F19: 起始点 Start Point | H19: 终止点 End Point | J19: 更换量(吨) Vol.Exchange (tons) | K19: 更换百分比(%) Exch. Percent | L19: 排放港口 Ports | M19: 排放日期 Date | N19: 排放量 Vol. (tons)
F21: 经度 LAT | G21: 纬度 LONG | H21: 经度 LAT | I21: 纬度 LONG
A23: 4LSP | B23: 43821 | C23: SINGAPORE | D23: 301 | E23: 43456 | F23: 06-16S | G23: 078-20E | H23: 06-06E | I23: 078-33E | J23: 301 | K23: 1 | L23: NIL | M23: NIL | N23: NIL
A24: 4LSS | B24: 43821 | C24: SINGAPORE | D24: 301 | E24: 43456 | F24: 06-16S | G24: 078-20E | H24: 06-06E | I24: 078-33E | J24: 301 | K24: 1 | L24: NIL | M24: NIL | N24: NIL
A25: 4SP | B25: 43821 | C25: SINGAPORE | D25: 301 | E25: 43456 | F25: 03-12S | G25: 082-36E | H25: 03-02S | I25: 082-49E | J25: 301 | K25: 1 | L25: NIL | M25: NIL | N25: NIL
A26: 4SS | B26: 43821 | C26: SINGAPORE | D26: 301 | E26: 43456 | F26: 03-12S | G26: 082-36E | H26: 03-02S | I26: 082-49E | J26: 301 | K26: 1 | L26: NIL | M26: NIL | N26: NIL
A27: 5SS | B27: 43821 | C27: SINGAPORE | D27: 301 | E27: 43456 | F27: 03-13S | G27: 082-37E | H27: 03-03S | I27: 082-50E | J27: 301 | K27: 1 | L27: NIL | M27: NIL | N27: NIL
A28: 6SS | B28: 43821 | C28: SINGAPORE | D28: 301 | E28: 43456 | F28: 03-14S | G28: 082-38E | H28: 03-04S | I28: 082-51E | J28: 301 | K28: 1 | L28: NIL | M28: NIL | N28: NIL
B30: 船长签名 | E30: 日期 | F30: ='Gen Inb'!X6 -> 46238
B31: Signature of Master | E31: Date

Sheet Q-Record In
A1: 出/入境船舶检验检疫记录单
B3: 报检编号： | T3: 检疫地点： | X3: ='Gen Inb'!S6 -> 南沙新港
B4: 船名 | E4: ='Gen Inb'!I6 -> 马士基奋进 | J4: 国籍 | P4: ='Gen Inb'!F8 -> 巴拿马 | T4: 类别 | V4: 客轮 | Y4: 货轮 | AC4: 其他
B5: 船员人数 | E5: ='Gen Inb'!H24 -> 19 | J5: 旅客人数 | P5: ='Gen Inb'!N24 -> nil | T5: 总吨 | V5: ='Gen Inb'!E12 -> 9562 | Y5: 净吨 | AC5: ='Gen Inb'!L12 -> 4523
B6: 启运/目的港 | E6: ='Gen Inb'!W8&"/"&'Gen Inb'!S6 -> 胡志明市/南沙新港 | P6: 启运/抵港日期 | V6: ='Gen Inb'!X6 -> 46238
B7: 停靠港 | E7: nil | J7: 载货种类 | P7: 集装箱 | T7: 总数/重量 | Y7: ='Gen Inb'!M21&"吨" -> 12059吨
B8: 装柜 | C8: 40'重: | D8: ='Cstm Outb'!E8 -> 0 | F8: 20'重: | H8: ='Cstm Outb'!D8 -> 0 | I8: 40'吉: | K8: 0 | M8: 20'吉: | O8: 0 | P8: 卸柜 | Q8: 40'重: | S8: ='Cstm Inb'!E9+'Cstm Inb'!I9+'Cstm Inb'!E11 -> 68 | U8: 20'重: | V8: ='Cstm Inb'!D9+'Cstm Inb'!H9+'Cstm Inb'!D11 -> 67 | W8: 40'吉: | Z8: ='Cstm Inb'!I11 -> 0 | AB8: 20'吉: | AD8: ='Cstm Inb'!H11 -> 0
B9: 货物是否已作熏蒸处理 | H9: 是 | L9: 否 | P9: 是否有植物性包装材料 | V9: 是 | AA9: 否
B10: 上航次 | E10: 自 | G10: ='Gen Outb'!G18 -> 胡志明市 | J10: 至 | L10: ='Gen Outb'!M18 -> 南沙新港 | P10: 装载货物名称 | V10: =P7 -> 集装箱
B11: 途经疫区类别 | H11: 鼠 疫 | L11: 霍 乱 | P11: 黄 热 病 | V11: 非 洲 猪 瘟
H12: 口蹄疫 | L12: 疯牛病 | P12: 其他动植物病虫害疫区 | V12: 其他烈性传染病
B13: 船员/旅客健康情况
B14: 船员/旅客因病变动情况 | P14: 无
B15: 压舱水情况 | H15: 有 | L15: 无 | P15: 是否在本港排放 | V15: 是 | AA15: 否
B16: 食品装载港 | H16: 香港 | P16: 饮用水装载港 | V16: 香港
H17: 良 好 | N17: 一 般 | R17: 差 | X17: 其 他
B18: 伴侣动物和/或鸟类 | P18: 有 | Q18: 来自 | AB18: 否
B19: 水果和/或蔬菜 | P19: 有 | Q19: 来自 | AB19: 否
B20: 花卉盆景 | P20: 有 | Q20: 来自 | AB20: 否
B21: 肉类、香肠、熏肉/家禽产品 | P21: 有 | Q21: 来自 | AB21: 否
B22: 其他类 | P22: 有 | Q22: 来自 | AB22: 否
B23: 船舶卫生证书情况 | H23: 有效 | L23: 过期 | P23: 签发港及日期 | Z23: 20 年 月 日
B24: 健康证书及预防接种情况 | H24: 有效 | L24: 过期
B25: 免予/卫生控制措施证书 | H25: 有效 | L25: 过期 | P25: 签发港及日期
B26: 检疫情况及处理措施：
B29: 检疫人员： | P29: 登轮时间： | T29: 20 | V29: 年 | X29: 月 | AA29: 日 | AC29: 时 | AD29: 分
B30: 审 核： | P30: 签证时间： | T30: 20 | V30: 年 | X30: 月 | AA30: 日 | AC30: 时 | AD30: 分

Sheet Q-Record Out
A1: 出/入境船舶检验检疫记录单
B3: 报检编号： | T3: 检疫地点： | X3: ='Gen Inb'!S6 -> 南沙新港
B4: 船名 | E4: ='Gen Inb'!I6 -> 马士基奋进 | J4: 国籍 | P4: ='Gen Inb'!F8 -> 巴拿马 | T4: 类别 | V4: 客轮 | Y4: 货轮 | AC4: 其他
B5: 船员人数 | E5: 17 | J5: 旅客人数 | P5: ='Gen Inb'!N24 -> nil | T5: 总吨 | V5: ='Gen Inb'!E12 -> 9562 | Y5: 净吨 | AC5: ='Gen Inb'!L12 -> 4523
B6: 启运/目的港 | E6: ='Gen Outb'!M18&"/"&'Gen Outb'!T18 -> 南沙新港/胡志明市 | P6: 启运/抵港日期 | V6: ='Gen Inb'!X6 -> 46238
B7: 停靠港 | E7: nil | J7: 载货种类 | P7: 集装箱 | T7: 总数/重量 | Y7: 7532 吨
B8: 装柜 | C8: 40'重: | D8: ='Cstm Outb'!E8 -> 0 | F8: 20'重: | H8: ='Cstm Outb'!D8 -> 0 | I8: 40'吉: | K8: 0 | M8: 20'吉: | O8: 0 | P8: 卸柜 | Q8: 40'重: | S8: ='Cstm Inb'!E9+'Cstm Inb'!I9+'Cstm Inb'!E11 -> 68 | U8: 20'重: | V8: ='Cstm Inb'!D9+'Cstm Inb'!H9+'Cstm Inb'!D11 -> 67 | W8: 40'吉: | Z8: ='Cstm Inb'!I11 -> 0 | AB8: 20'吉: | AD8: ='Cstm Inb'!H11 -> 0
B9: 货物是否已作熏蒸处理 | H9: 是 | L9: 否 | P9: 是否有植物性包装材料 | V9: 是 | AA9: 否
B10: 上航次 | E10: 自 | G10: ='Gen Inb'!W8 -> 胡志明市 | J10: 至 | L10: 南沙新港 | P10: 装载货物名称 | V10: =P7 -> 集装箱
B11: 途经疫区类别 | H11: 鼠 疫 | L11: 霍 乱 | P11: 黄 热 病 | V11: 非 洲 猪 瘟
H12: 口蹄疫 | L12: 疯牛病 | P12: 其他动植物病虫害疫区 | V12: 其他烈性传染病
B13: 船员/旅客健康情况 | P13: 良好
B14: 船员/旅客因病变动情况 | P14: 无
B15: 压舱水情况 | H15: 有 | L15: 无 | P15: 是否在本港排放 | V15: 是 | AA15: 否
B16: 食品装载港 | P16: 饮用水装载港
B17: 船舶卫生状况 | H17: 良 好 | N17: 一 般 | R17: 差 | X17: 其 他
B18: 伴侣动物和/或鸟类 | P18: 有 | Q18: 来自 | AB18: 否
B19: 水果和/或蔬菜 | P19: 有 | Q19: 来自 | AB19: 否
B20: 花卉盆景 | P20: 有 | Q20: 来自 | AB20: 否
B21: 肉类、香肠、熏肉/家禽产品 | P21: 有 | Q21: 来自 | AB21: 否
B22: 其他类 | P22: 有 | Q22: 来自 | AB22: 否
B23: 船舶卫生证书情况 | H23: 有效 | L23: 过期 | P23: 签发港及日期 | Z23: 20 年 月 日
B24: 健康证书及预防接种情况 | H24: 有效 | L24: 过期
B25: 免予/卫生控制措施证书 | H25: 有效 | L25: 过期 | P25: 签发港及日期
B26: 检疫情况及处理措施：
B29: 检疫人员： | P29: 登轮时间： | T29: 20 | V29: 年 | X29: 月 | AA29: 日 | AC29: 时 | AD29: 分
B30: 审 核： | P30: 签证时间： | T30: 20 | V30: 年 | X30: 月 | AA30: 日 | AC30: 时 | AD30: 分

Sheet Q-Inb
D1: 交通运输工具入境检疫签证申请单
C3: APPLICATION FORM OF QUARANTINE INSPECTION ON
D4: IMPORT OF CONVEYANCE
F6: 编号：
B8: 中华人民共和国南沙出入境检验检疫局：
B9: NANSHA Entry-Exit inspection and Quarantine Bureau of the People’s Republic of China:
C11: 现向贵局申请本交通工具入境检疫,并根据检查结果发给入境检疫证。
C12: I hereby apply for a quarantine inspection of import on my conveyance and issue a quarantine
B13: certificate for import of conveyance on the basis of the inspection results.
B15: 交通工具名称及号码 | D15: ='Gen Inb'!I6 -> 马士基奋进 | E15: 国籍 | F15: ='Gen Inb'!F8 -> 巴拿马
B16: Name & No. of Conveyance | D16: ='Gen Inb'!I7 -> ERASMUS EFFORT | E16: Nationality | F16: ='Gen Inb'!F9 -> PANAMA
B17: 登记号/IMO编号 | D17: ='Gen Inb'!I10 -> IMO:1032452 | E17: 所有人 | F17: 马士基中国航运
B18: Registration/IMO No. | E18: Owner of Conveyance | F18: MSK
B19: 启运港/站 | D19: ='Gen Inb'!W8 -> 胡志明市 | E19: 途中停靠港/站
B20: Port/Station of Departure | D20: ='Gen Inb'!W9 -> HO CHI MINH CITY | E20: Port/Station of Call | F20: NIL
B21: 到达港/站 | D21: ='Gen Inb'!S6 -> 南沙新港 | E21: 到港日期及时间 | G21: ='Gen Inb'!X6 -> 46238
B22: Port/Station of Arrival | D22: ='Gen Inb'!S7 -> NANSHA NEW PORT | E22: Date and Time of Arrival
B23: 总吨 | D23: ='Gen Inb'!E12 -> 9562 | E23: 仓/箱节数 | G23: NIL
B24: Gross Tons | E24: Quantity of Cabins/Carriages
B25: 船员人数 | D25: ——20人—— | E25: 代理人 | G25: ='Gen Inb'!P12 -> 0
B26: Crew member | D26: TWENTY PERSONS | E26: Agent of Conveyance | G26: =IF(G25="广州联合国际船舶代理有限公司","UNISCOGZ","")
B27: 联系人 | D27: ='Gen Inb'!V12 -> 0 | E27: 联系电话 | F27: ='Gen Inb'!V14 -> 0
B28: Agent of Conveyance | E28: Telephone
B29: *签字 | E29: 申请日期及时间 | G29: =TODAY() -> 46236
B30: Captain Signature | E30: Date and Time of Application
C32: 附随单据 | D32: 船员名单 □ | E32: 载货清单 □ | F32: 食品仓存货清单 □
C33: Bills Attached | D33: Name List of Crew | E33: List of Goods | F33: List of Reserved Foods
B34: *签字栏应由船长、机长或车长签字 | F34: 广东出入境检验检疫局制

Sheet Q-Outb
D1: 交通运输工具出境检疫签证申请单
C3: APPLICATION FORM OF QUARANTINE INSPECTION ON
D4: EXPORT OF CONVEYANCE
F6: 编号：
B8: 中华人民共和国南沙出入境检验检疫局：
B9: NANSHA Entry-Exit inspection and Quarantine Bureau of the People’s Republic of China:
C11: 现向贵局申请本交通工具出境检疫,并根据检查结果发给出境检疫证。
C12: I hereby apply for a quarantine inspection of export on my conveyance and issue a quarantine
B13: certificate for export of conveyance on the basis of the inspection results.
B15: 交通工具名称及号码 | D15: ='Gen Inb'!I6 -> 马士基奋进 | E15: 国籍 | F15: ='Gen Inb'!F8 -> 巴拿马
B16: Name & No. of Conveyance | D16: ='Gen Inb'!I7 -> ERASMUS EFFORT | E16: Nationality | F16: ='Gen Inb'!F9 -> PANAMA
B17: 登记号/IMO编号 | D17: ='Gen Inb'!I10 -> IMO:1032452 | E17: 所有人 | F17: 马士基中国航运
B18: Registration/IMO No. | E18: Owner of Conveyance | F18: MSK
B19: 启运港/站 | D19: ='Gen Outb'!S6 -> 南沙新港 | E19: 途中停靠港/站
B20: Port/Station of Departure | D20: ='Gen Outb'!S7 -> NANSHA NEW PORT | E20: Port/Station of Call | F20: NIL
B21: 到达港/站 | D21: ='Gen Outb'!W8 -> 胡志明市 | E21: 离港日期及时间 | G21: ='Gen Outb'!X6 -> 44160
B22: Port/Station of Arrival | D22: ='Gen Outb'!W9 -> HO CHI MINH CITY | E22: Date and Time of Departure
B23: 总吨 | D23: ='Gen Inb'!E12 -> 9562 | E23: 仓/箱节数 | G23: NIL
B24: Gross Tons | E24: Quantity of Cabins/Carriages
B25: 船员人数 | D25: ——20人—— | E25: 代理人 | G25: ='Gen Inb'!P12 -> 0
B26: Crew member | D26: TWENTY PERSONS | E26: Agent of Conveyance | G26: =IF(G25="广州联合国际船舶代理有限公司","UNISCOGZ","")
B27: 联系人 | D27: ='Gen Inb'!V12 -> 0 | E27: 联系电话 | F27: ='Gen Inb'!V14 -> 0
B28: Agent of Conveyance | E28: Telephone
B29: *签字 | E29: 申请日期及时间 | G29: =TODAY() -> 46236
B30: Captain Signature | E30: Date and Time of Application
C32: 附随单据 | D32: 船员名单 □ | E32: 载货清单 □ | F32: 食品仓存货清单 □
C33: Bills Attached | D33: Name List of Crew | E33: List of Goods | F33: List of Reserved Foods
B34: *签字栏应由船长、机长或车长签字 | F34: 广东出入境检验检疫局制

Sheet Q-Process
E1: 龙穴岛办事处
E2: 船舶检疫工作流程登记表
G4: 报检编号：
B6: 检务计收费 | C6: 受理报检 | F6: 日 期
C7: 船舶检疫：￥ | E7: 签发证：￥ | G7: 其他：￥ | O7: ；
C8: 合计：￥ （元）
C9: 收费人 | F9: 日 期
B10: 审核人： | H10: 20 年 月 日
B11: 说明：因航行港澳船舶通过自动应答系统自行打印出（入）境检疫证，港澳进行出（入）境报检无需填写以下表格。
B12: 签发人： | H12: 20 年 月 日
B13: 备 注
B23: 经办人： | D23: 20 年 月 日 | F23: 出（入）境检疫证/卫生证/卫生控制证书印刷号
B24: 批准人： | D24: 20 年 月 日
B25: 说明： | C25: 本表加附在报检面单之后

Sheet Formalities
C2: 广州联合国际船舶代理有限公司
D3: ='Gen Inb'!I6 -> 马士基奋进 | H3: ='Gen Inb'!F8 -> 巴拿马
D5: ='Gen Inb'!I7 -> ERASMUS EFFORT | H5: ='Gen Inb'!K14 -> 二期W

Sheet IMO Gen Inb
K2: IN
C4: ='Gen Inb'!I6&""&'Gen Inb'!I7 -> 马士基奋进ERASMUS EFFORT | J4: ='Parts A'!B5 -> IMO:1032452
C5: ='Parts A'!B6 -> 3E8968 | J5: ='Gen Inb'!S6&""&'Gen Inb'!S7 -> 南沙新港NANSHA NEW PORT
C6: ='Gen Inb'!X6 -> 46238 | E6: ='Gen Inb'!X7 -> 0 | F6: 时 | J6: ='Parts A'!E3&""&'Parts A'!E4 -> 巴拿马PANAMA
C7: ='Gen Inb'!M8 -> 李继祥 | J7: ='Gen Inb'!W8&""&'Gen Inb'!W9 -> 胡志明市HO CHI MINH CITY
G9: ='Gen Inb'!P12&"："&'Gen Inb'!V12 -> ：
B10: ='Parts A'!E5 -> 9562 | E10: ='Parts A'!G5 -> 4523 | G10: ='Gen Inb'!O14&" "&'Gen Inb'!V14 -> 91440101MA5AQA0F7M
D11: ='Gen Inb'!K14 -> 二期W
B13: ='Gen Inb'!G18&" "&"("&'Gen Inb'!G19&")"&"——"&'Gen Inb'!M18&" "&"("&'Gen Inb'!M19&")" -> 胡志明市 (HO CHI MINH CITY)——南沙新港 (NANSHA NEW PORT)
D15: ='Gen Inb'!J21&'Gen Inb'!M21&" "&'Gen Inb'!O21 -> 总重量：12059 吨
C16: ='Gen Inb'!E22&'Gen Inb'!F22&" "&'Gen Inb'!P22&'Gen Inb'!R22&" "&'Gen Inb'!T22&'Gen Inb'!V22&'Gen Inb'!W22&" "&'Gen Inb'!X22 -> 进口柜：20F×67, 40F×68, 20E×0, 40E×0 总共：203 TEU，2919 吨；
C17: ='Gen Inb'!E23&'Gen Inb'!F23&" "&'Gen Inb'!P23&'Gen Inb'!R23&" "&'Gen Inb'!T23&'Gen Inb'!V23&'Gen Inb'!W23&" "&'Gen Inb'!X23 -> 过境柜：20F×133, 40F×324 总共：781 TEU，9140 吨；
C19: =COUNTA('Crew Outb'!C11:C30) -> 20 | F19: ='Gen Inb'!N24 -> nil
I20: ='Gen Inb'!R24 -> 无武器
I21: ="船公司："&'Gen Inb'!R28 -> 船公司：马士基（中国）航运有限公司青岛分公司
C22: 1
C24: 1 | F24: nil
I26: =YEAR('Gen Inb'!X6) -> 2026 | K26: =MONTH('Gen Inb'!X6) -> 8 | L26: =DAY('Gen Inb'!X6) -> 4

Sheet IMO Gen Outb
L2: OUT
C4: ='IMO Gen Inb'!C4 -> 马士基奋进ERASMUS EFFORT | J4: ='IMO Gen Inb'!J4 -> IMO:1032452
C5: ='Parts A'!B6 -> 3E8968 | J5: ='IMO Gen Inb'!J5 -> 南沙新港NANSHA NEW PORT
C6: ='Gen Outb'!X6 -> 44160 | E6: ='Gen Outb'!X7 -> 0 | F6: 时 | J6: ='IMO Gen Inb'!J6 -> 巴拿马PANAMA
C7: ='IMO Gen Inb'!C7 -> 李继祥 | J7: ='Gen Outb'!W8&""&'Gen Outb'!W9 -> 胡志明市HO CHI MINH CITY
G9: ='Gen Inb'!P12&"："&'Gen Inb'!V12 -> ：
B10: ='IMO Gen Inb'!B10 -> 9562 | E10: ='IMO Gen Inb'!E10 -> 4523 | G10: ='Gen Inb'!O14&" "&'Gen Inb'!V14 -> 91440101MA5AQA0F7M
D11: ='IMO Gen Inb'!D11 -> 二期W
B13: ='Gen Outb'!M18&" "&"("&'Gen Outb'!M19&")"&"——"&'Gen Outb'!T18&" "&"("&'Gen Outb'!T19&")" -> 南沙新港 (NANSHA NEW PORT)——胡志明市 (HO CHI MINH CITY)
D15: ='Gen Outb'!J21&'Gen Outb'!M21&" "&'Gen Outb'!O21 -> 总重量：17396.5 吨
C16: ='Gen Outb'!E22&'Gen Outb'!F22&" "&'Gen Outb'!P22&'Gen Outb'!R22&" "&'Gen Outb'!T22&'Gen Outb'!V22&'Gen Outb'!W22&" "&'Gen Outb'!X22 -> 出口柜：NIL 总共：0 TEU，8256.5 吨；
C17: ='Gen Inb'!E23&'Gen Inb'!F23&" "&'Gen Inb'!P23&'Gen Inb'!R23&" "&'Gen Inb'!T23&'Gen Inb'!V23&'Gen Inb'!W23&" "&'Gen Inb'!X23 -> 过境柜：20F×133, 40F×324 总共：781 TEU，9140 吨；
C19: 20 | F19: ='Gen Inb'!N24 -> nil
I20: ='IMO Gen Inb'!I20 -> 无武器
I21: ='IMO Gen Inb'!I21 -> 船公司：马士基（中国）航运有限公司青岛分公司
C22: 1
C24: 1 | F24: 0
I26: =YEAR('Gen Outb'!X6) -> 2020 | K26: =MONTH('Gen Outb'!X6) -> 11 | L26: =DAY('Gen Outb'!X6) -> 25

Sheet IMO Cgo Inb
G2: IN
C3: ='IMO Gen Inb'!C4 -> 马士基奋进ERASMUS EFFORT | G3: ='IMO Gen Inb'!J4 -> IMO:1032452 | J3: ='IMO Gen Inb'!C5 -> 3E8968
C4: ='IMO Gen Inb'!J5 -> 南沙新港NANSHA NEW PORT | H4: ='IMO Gen Inb'!J6 -> 巴拿马PANAMA
C5: ='IMO Gen Inb'!C7 -> 李继祥 | H5: ='IMO Gen Inb'!J7 -> 胡志明市HO CHI MINH CITY
E10: ='Gen Inb'!J21&'Gen Inb'!M21&" "&'Gen Inb'!O21 -> 总重量：12059 吨
D12: ='Gen Inb'!E22&'Gen Inb'!F22 -> 进口柜：20F×67, 40F×68, 20E×0, 40E×0
E13: ='Gen Inb'!P22&'Gen Inb'!R22&" "&'Gen Inb'!T22&'Gen Inb'!V22&'Gen Inb'!W22&" "&'Gen Inb'!X22 -> 总共：203 TEU，2919 吨；
D14: ='Gen Inb'!E23&'Gen Inb'!F23 -> 过境柜：20F×133, 40F×324
E15: ='Gen Inb'!P23&'Gen Inb'!R23&" "&'Gen Inb'!T23&'Gen Inb'!V23&'Gen Inb'!W23&" "&'Gen Inb'!X23 -> 总共：781 TEU，9140 吨；
D23: ='Gen Inb'!P12&"："&'Gen Inb'!V12 -> ：
D24: ='Gen Inb'!O14&"，"&'Gen Inb'!V14 -> 91440101MA5AQA0F7M，
H28: =YEAR('Gen Inb'!X6) -> 2026 | I28: =MONTH('Gen Inb'!X6) -> 8 | J28: =DAY('Gen Inb'!X6) -> 4

Sheet IMO Cgo Outb
H2: OUT
C3: ='IMO Gen Outb'!C4 -> 马士基奋进ERASMUS EFFORT | G3: ='IMO Gen Outb'!J4 -> IMO:1032452 | J3: ='IMO Gen Outb'!C5 -> 3E8968
C4: ='IMO Gen Outb'!J5 -> 南沙新港NANSHA NEW PORT | H4: ='IMO Gen Outb'!J6 -> 巴拿马PANAMA
C5: ='IMO Gen Outb'!C7 -> 李继祥 | H5: ='IMO Gen Outb'!J7 -> 胡志明市HO CHI MINH CITY
E11: ='Gen Outb'!J21&'Gen Outb'!M21&" "&'Gen Outb'!O21 -> 总重量：17396.5 吨
D12: ='Gen Outb'!E22&'Gen Outb'!F22 -> 出口柜：NIL
E13: ='Gen Outb'!P22&'Gen Outb'!R22&" "&'Gen Outb'!T22&'Gen Outb'!V22&'Gen Outb'!W22&" "&'Gen Outb'!X22 -> 总共：0 TEU，8256.5 吨；
D14: ='Gen Inb'!E23&'Gen Inb'!F23 -> 过境柜：20F×133, 40F×324
E15: ='Gen Inb'!P23&'Gen Inb'!R23&" "&'Gen Inb'!T23&'Gen Inb'!V23&'Gen Inb'!W23&" "&'Gen Inb'!X23 -> 总共：781 TEU，9140 吨；
D23: ='Gen Inb'!P12&"："&'Gen Inb'!V12 -> ：
D24: ='Gen Inb'!O14&"，"&'Gen Inb'!V14 -> 91440101MA5AQA0F7M，
H28: =YEAR('Gen Outb'!X6) -> 2020 | I28: =MONTH('Gen Outb'!X6) -> 11 | J28: =DAY('Gen Outb'!X6) -> 25

Sheet IMO Crew Inb
H3: IN
C4: ='IMO Gen Inb'!C4 -> 马士基奋进ERASMUS EFFORT | H4: ='IMO Gen Inb'!J4 -> IMO:1032452 | L4: ='IMO Gen Inb'!C5 -> 3E8968
C5: ='IMO Gen Inb'!J5 -> 南沙新港NANSHA NEW PORT | I5: ='IMO Gen Inb'!C6 -> 46238
C6: ='IMO Gen Inb'!J6 -> 巴拿马PANAMA | I6: ='IMO Gen Inb'!J7 -> 胡志明市HO CHI MINH CITY
B8: =IF(C8<>"",COUNTA(C$8:C8),"") -> 1 | C8: =IF('Crew Inb'!C11<>"",'Crew Inb'!C11&" "&'Crew Inb'!D11,"") -> 李继祥 | D8: =IF('Crew Inb'!E11<>"",'Crew Inb'!E11,"") -> M | E8: =IF('Crew Inb'!F11<>"",'Crew Inb'!F11,"") -> Master | F8: =IF('Crew Inb'!G11<>"",'Crew Inb'!G11,"") -> Montenegro | G8: =IF('Crew Inb'!H11<>"",'Crew Inb'!H11,"") -> 29228 | H8: =IF('Crew Inb'!I11<>"",'Crew Inb'!I11,"") -> Montenegro | J8: 护照 | K8: =IF('Crew Inb'!K11<>"",'Crew Inb'!K11,"") -> B42BR8005
B9: =IF(C9<>"",COUNTA(C$8:C9),"") -> 2 | C9: =IF('Crew Inb'!C12<>"",'Crew Inb'!C12&" "&'Crew Inb'!D12,"") -> FERNANDEZ REYNALDO JR | D9: =IF('Crew Inb'!E12<>"",'Crew Inb'!E12,"") -> M | E9: =IF('Crew Inb'!F12<>"",'Crew Inb'!F12,"") -> Chief Officer | F9: =IF('Crew Inb'!G12<>"",'Crew Inb'!G12,"") -> Ukraine | G9: =IF('Crew Inb'!H12<>"",'Crew Inb'!H12,"") -> 24515 | H9: =IF('Crew Inb'!I12<>"",'Crew Inb'!I12,"") -> Ukraine | J9: 护照 | K9: =IF('Crew Inb'!K12<>"",'Crew Inb'!K12,"") -> AB498691
B10: =IF(C10<>"",COUNTA(C$8:C10),"") -> 3 | C10: =IF('Crew Inb'!C13<>"",'Crew Inb'!C13&" "&'Crew Inb'!D13,"") -> FERNANDEZ REYNALDO JR | D10: =IF('Crew Inb'!E13<>"",'Crew Inb'!E13,"") -> M | E10: =IF('Crew Inb'!F13<>"",'Crew Inb'!F13,"") -> Second Officer | F10: =IF('Crew Inb'!G13<>"",'Crew Inb'!G13,"") -> Filipino | G10: =IF('Crew Inb'!H13<>"",'Crew Inb'!H13,"") -> 29167 | H10: =IF('Crew Inb'!I13<>"",'Crew Inb'!I13,"") -> Filipino | J10: 护照 | K10: =IF('Crew Inb'!K13<>"",'Crew Inb'!K13,"") -> P0392496A
B11: =IF(C11<>"",COUNTA(C$8:C11),"") -> 4 | C11: =IF('Crew Inb'!C14<>"",'Crew Inb'!C14&" "&'Crew Inb'!D14,"") -> GONZAGA JOHN BRIAN CANALITA | D11: =IF('Crew Inb'!E14<>"",'Crew Inb'!E14,"") -> M | E11: =IF('Crew Inb'!F14<>"",'Crew Inb'!F14,"") -> Third Officer | F11: =IF('Crew Inb'!G14<>"",'Crew Inb'!G14,"") -> Filipino | G11: =IF('Crew Inb'!H14<>"",'Crew Inb'!H14,"") -> 34095 | H11: =IF('Crew Inb'!I14<>"",'Crew Inb'!I14,"") -> Filipino | J11: 护照 | K11: =IF('Crew Inb'!K14<>"",'Crew Inb'!K14,"") -> EC3697674
B12: =IF(C12<>"",COUNTA(C$8:C12),"") -> 5 | C12: =IF('Crew Inb'!C15<>"",'Crew Inb'!C15&" "&'Crew Inb'!D15,"") -> DYACHENKO VASYL | D12: =IF('Crew Inb'!E15<>"",'Crew Inb'!E15,"") -> M | E12: =IF('Crew Inb'!F15<>"",'Crew Inb'!F15,"") -> Chief Engineer | F12: =IF('Crew Inb'!G15<>"",'Crew Inb'!G15,"") -> Ukraine | G12: =IF('Crew Inb'!H15<>"",'Crew Inb'!H15,"") -> 27961 | H12: =IF('Crew Inb'!I15<>"",'Crew Inb'!I15,"") -> Ukraine | J12: 护照 | K12: =IF('Crew Inb'!K15<>"",'Crew Inb'!K15,"") -> AB406216
B13: =IF(C13<>"",COUNTA(C$8:C13),"") -> 6 | C13: =IF('Crew Inb'!C16<>"",'Crew Inb'!C16&" "&'Crew Inb'!D16,"") -> BALAKIN OLEG | D13: =IF('Crew Inb'!E16<>"",'Crew Inb'!E16,"") -> M | E13: =IF('Crew Inb'!F16<>"",'Crew Inb'!F16,"") -> Second Engineer | F13: =IF('Crew Inb'!G16<>"",'Crew Inb'!G16,"") -> Ukraine | G13: =IF('Crew Inb'!H16<>"",'Crew Inb'!H16,"") -> 24595 | H13: =IF('Crew Inb'!I16<>"",'Crew Inb'!I16,"") -> Ukraine | J13: 护照 | K13: =IF('Crew Inb'!K16<>"",'Crew Inb'!K16,"") -> AB565162
